Workbook
Name _QR001: [1]Control!$H$2
Name _QR001: [1]Control!$H$2
Name _QR001: [1]Control!$H$2
Name _QR001: [1]Control!$H$2
Name _QR001: [2]Control!$H$2
Name _QR002: [1]Control!$H$3
Name _QR002: [1]Control!$H$3
Name _QR002: [1]Control!$H$3
Name _QR002: [1]Control!$H$3
Name _QR002: [2]Control!$H$3
Name _QR003: [1]Control!$H$4
Name _QR003: [1]Control!$H$4
Name _QR003: [1]Control!$H$4
Name _QR003: [1]Control!$H$4
Name _QR003: [2]Control!$H$4
Name _QR004: [1]Control!$H$5
Name _QR004: [1]Control!$H$5
Name _QR004: [1]Control!$H$5
Name _QR004: [1]Control!$H$5
Name _QR004: [2]Control!$H$5
Name _QR011: [1]Control!$I$2
Name _QR011: [1]Control!$I$2
Name _QR011: [1]Control!$I$2
Name _QR011: [1]Control!$I$2
Name _QR011: [2]Control!$I$2
Name _QR012: [1]Control!$I$3
Name _QR012: [1]Control!$I$3
Name _QR012: [1]Control!$I$3
Name _QR012: [1]Control!$I$3
Name _QR012: [2]Control!$I$3
Name _QR013: [1]Control!$I$4
Name _QR013: [1]Control!$I$4
Name _QR013: [1]Control!$I$4
Name _QR013: [1]Control!$I$4
Name _QR013: [2]Control!$I$4
Name _QR014: [1]Control!$I$5
Name _QR014: [1]Control!$I$5
Name _QR014: [1]Control!$I$5
Name _QR014: [1]Control!$I$5
Name _QR014: [2]Control!$I$5
Name _QR021: [1]Control!$J$2
Name _QR021: [1]Control!$J$2
Name _QR021: [1]Control!$J$2
Name _QR021: [1]Control!$J$2
Name _QR021: [2]Control!$J$2
Name _QR022: [1]Control!$J$3
Name _QR022: [1]Control!$J$3
Name _QR022: [1]Control!$J$3
Name _QR022: [1]Control!$J$3
Name _QR022: [2]Control!$J$3
Name _QR023: [1]Control!$J$4
Name _QR023: [1]Control!$J$4
Name _QR023: [1]Control!$J$4
Name _QR023: [1]Control!$J$4
Name _QR023: [2]Control!$J$4
Name _QR024: [1]Control!$J$5
Name _QR024: [1]Control!$J$5
Name _QR024: [1]Control!$J$5
Name _QR024: [1]Control!$J$5
Name _QR024: [2]Control!$J$5

Sheet Quarter (nominal value)
A2: Amount outstanding of debt securities issued in domestic market at nominal value
A3: (on date)
A4: Millions of Rubles
B5: 41275 | C5: 41365 | D5: 41456 | E5: 41548 | F5: 41640 | G5: 41730 | H5: 41821 | I5: 41913 | J5: 42005 | K5: 42095 | L5: 42186 | M5: 42278 | N5: 42370 | O5: 42461 | P5: 42552 | Q5: 42644 | R5: 42736 | S5: 42826 | T5: 42917 | U5: 43009 | V5: 43101 | W5: 43191 | X5: 43282 | Y5: 43374 | Z5: 01.01.2019* | AA5: 43556 | AB5: 43647 | AC5: 43739 | AD5: 43831 | AE5: 43922 | AF5: 44013 | AG5: 44105 | AH5: 44197 | AI5: 44287 | AJ5: 44378 | AK5: 44470 | AL5: 44562 | AM5: 44652 | AN5: 44743 | AO5: 44835 | AP5: 44927 | AQ5: 45017 | AR5: 45108 | AS5: 45200 | AT5: 45292 | AU5: 45383 | AV5: 45474 | AW5: 45566 | AX5: 45658 | AY5: 45748 | AZ5: 45839 | BA5: 45931 | BB5: 46023
A6: Amount outstanding of debt securities - total
A7: Total | B7: 8516504 | C7: 8613445 | D7: 8913700 | E7: 9286909 | F7: 9779946 | G7: 9955872 | H7: 10060011 | I7: 10296614 | J7: 12237465 | K7: 12555631 | L7: 12883426 | M7: 13064426 | N7: 13600298 | O7: 13669956 | P7: 14264113 | Q7: 14479652 | R7: 15616388 | S7: 16197232 | T7: 16941460 | U7: 17847276 | V7: 19144405 | W7: 20235101 | X7: 20465232 | Y7: 20991227 | Z7: 21227588 | AA7: 21908808 | AB7: 23182889 | AC7: 22978950 | AD7: 25070699 | AE7: 25633288 | AF7: 25715007 | AG7: 27474233 | AH7: 31557716 | AI7: 32049396 | AJ7: 32805309 | AK7: 33891217 | AL7: 33895352 | AM7: 33712879 | AN7: 33186753 | AO7: 33644123 | AP7: 38196529 | AQ7: 39686752 | AR7: 41532038 | AS7: 43293476 | AT7: 45350008 | AU7: 46859535 | AV7: 47485869 | AW7: 49734403 | AX7: 56954626 | AY7: 57945806 | AZ7: 60519471 | BA7: 63791443 | BB7: 68005551
A8: Short-term | B8: 13000 | C8: 15000 | D8: 15000 | E8: 15000 | F8: 2000 | G8: 873 | H8: 15873 | I8: 15873 | J8: 0 | K8: 0 | L8: 0 | M8: 0 | N8: 0 | O8: 3000 | P8: 3010 | Q8: 3416 | R8: 4086 | S8: 71413 | T8: 81738 | U8: 165588 | V8: 399890 | W8: 1225796 | X8: 1196256 | Y8: 1540427 | Z8: 1396218 | AA8: 1537398 | AB8: 1814693 | AC8: 981499 | AD8: 2115601 | AE8: 1713463 | AF8: 871475 | AG8: 958202 | AH8: 707112 | AI8: 756482 | AJ8: 723835 | AK8: 691104 | AL8: 154503 | AM8: 147605 | AN8: 139711 | AO8: 234748 | AP8: 208173 | AQ8: 196119 | AR8: 154967 | AS8: 296876 | AT8: 347640 | AU8: 461426 | AV8: 446933 | AW8: 348862 | AX8: 411058 | AY8: 460775 | AZ8: 487419 | BA8: 553905 | BB8: 492925
A9: Long-term | B9: 8503504 | C9: 8598445 | D9: 8898700 | E9: 9271909 | F9: 9777946 | G9: 9954999 | H9: 10044138 | I9: 10280741 | J9: 12237465 | K9: 12555631 | L9: 12883426 | M9: 13064426 | N9: 13600298 | O9: 13666956 | P9: 14261103 | Q9: 14476237 | R9: 15612302 | S9: 16125819 | T9: 16859722 | U9: 17681688 | V9: 18744515 | W9: 19009304 | X9: 19268976 | Y9: 19450800 | Z9: 19831370 | AA9: 20371410 | AB9: 21368196 | AC9: 21997452 | AD9: 22955098 | AE9: 23919825 | AF9: 24843532 | AG9: 26516032 | AH9: 30850604 | AI9: 31292914 | AJ9: 32081473 | AK9: 33200113 | AL9: 33740849 | AM9: 33565274 | AN9: 33047042 | AO9: 33409375 | AP9: 37988356 | AQ9: 39490634 | AR9: 41377071 | AS9: 42996601 | AT9: 45002368 | AU9: 46398109 | AV9: 47038936 | AW9: 49385541 | AX9: 56543568 | AY9: 57485031 | AZ9: 60032052 | BA9: 63237538 | BB9: 67512626
A10: Long term, with a remaining maturity up to and including 1 year | Z10: 1222726 | AA10: 1401520 | AB10: 1478618 | AC10: 1431756 | AD10: 1768259 | AE10: 2171695 | AF10: 2410824 | AG10: 2860092 | AH10: 2799286 | AI10: 2338287 | AJ10: 1928866 | AK10: 1984694 | AL10: 2261708 | AM10: 2505181 | AN10: 2582574 | AO10: 2678935 | AP10: 2357902 | AQ10: 2588135 | AR10: 2888416 | AS10: 2976886 | AT10: 3451840 | AU10: 3738375 | AV10: 3584464 | AW10: 3852394 | AX10: 4559632 | AY10: 4468526 | AZ10: 5087753 | BA10: 5750697 | BB10: 5874459
A11: Long term, with a remaining maturity more than 1 year | Z11: 18608644 | AA11: 18969891 | AB11: 19889578 | AC11: 20565696 | AD11: 21186839 | AE11: 21748130 | AF11: 22432709 | AG11: 23655940 | AH11: 28051318 | AI11: 28954626 | AJ11: 30152607 | AK11: 31215419 | AL11: 31479141 | AM11: 31060093 | AN11: 30464468 | AO11: 30730440 | AP11: 35630455 | AQ11: 36902499 | AR11: 38488655 | AS11: 40019715 | AT11: 41550528 | AU11: 42659734 | AV11: 43454472 | AW11: 45533147 | AX11: 51983936 | AY11: 53016506 | AZ11: 54944299 | BA11: 57486841 | BB11: 61638167
A12: Central bank | B12: 0 | C12: 0 | D12: 0 | E12: 0 | F12: 0 | G12: 0 | H12: 0 | I12: 0 | J12: 0 | K12: 0 | L12: 0 | M12: 0 | N12: 0 | O12: 0 | P12: 0 | Q12: 0 | R12: 0 | S12: 0 | T12: 0 | U12: 149530 | V12: 352321 | W12: 1128680 | X12: 1112149 | Y12: 1486459 | Z12: 1374230 | AA12: 1500000 | AB12: 1700000 | AC12: 800000 | AD12: 1936705 | AE12: 1544228 | AF12: 708128 | AG12: 818535 | AH12: 574227 | AI12: 645069 | AJ12: 626380 | AK12: 603353 | AL12: 0 | AM12: 0 | AN12: 0 | AO12: 0 | AP12: 0 | AQ12: 0 | AR12: 0 | AS12: 0 | AT12: 0 | AU12: 0 | AV12: 0 | AW12: 0 | AX12: 0 | AY12: 0 | AZ12: 0 | BA12: 0 | BB12: 0
A13: Short-term | B13: 0 | C13: 0 | D13: 0 | E13: 0 | F13: 0 | G13: 0 | H13: 0 | I13: 0 | J13: 0 | K13: 0 | L13: 0 | M13: 0 | N13: 0 | O13: 0 | P13: 0 | Q13: 0 | R13: 0 | S13: 0 | T13: 0 | U13: 149530 | V13: 352321 | W13: 1128680 | X13: 1112149 | Y13: 1486459 | Z13: 1374230 | AA13: 1500000 | AB13: 1700000 | AC13: 800000 | AD13: 1936705 | AE13: 1544228 | AF13: 708128 | AG13: 818535 | AH13: 574227 | AI13: 645069 | AJ13: 626380 | AK13: 603353 | AL13: 0 | AM13: 0 | AN13: 0 | AO13: 0 | AP13: 0 | AQ13: 0 | AR13: 0 | AS13: 0 | AT13: 0 | AU13: 0 | AV13: 0 | AW13: 0 | AX13: 0 | AY13: 0 | AZ13: 0 | BA13: 0 | BB13: 0
A14: Long-term | B14: 0 | C14: 0 | D14: 0 | E14: 0 | F14: 0 | G14: 0 | H14: 0 | I14: 0 | J14: 0 | K14: 0 | L14: 0 | M14: 0 | N14: 0 | O14: 0 | P14: 0 | Q14: 0 | R14: 0 | S14: 0 | T14: 0 | U14: 0 | V14: 0 | W14: 0 | X14: 0 | Y14: 0 | Z14: 0 | AA14: 0 | AB14: 0 | AC14: 0 | AD14: 0 | AE14: 0 | AF14: 0 | AG14: 0 | AH14: 0 | AI14: 0 | AJ14: 0 | AK14: 0 | AL14: 0 | AM14: 0 | AN14: 0 | AO14: 0 | AP14: 0 | AQ14: 0 | AR14: 0 | AS14: 0 | AT14: 0 | AU14: 0 | AV14: 0 | AW14: 0 | AX14: 0 | AY14: 0 | AZ14: 0 | BA14: 0 | BB14: 0
A15: Long term, with a remaining maturity up to and including 1 year | Z15: 0 | AA15: 0 | AB15: 0 | AC15: 0 | AD15: 0 | AE15: 0 | AF15: 0 | AG15: 0 | AH15: 0 | AI15: 0 | AJ15: 0 | AK15: 0 | AL15: 0 | AM15: 0 | AN15: 0 | AO15: 0 | AP15: 0 | AQ15: 0 | AR15: 0 | AS15: 0 | AT15: 0 | AU15: 0 | AV15: 0 | AW15: 0 | AX15: 0 | AY15: 0 | AZ15: 0 | BA15: 0 | BB15: 0
A16: Long term, with a remaining maturity more than 1 year | Z16: 0 | AA16: 0 | AB16: 0 | AC16: 0 | AD16: 0 | AE16: 0 | AF16: 0 | AG16: 0 | AH16: 0 | AI16: 0 | AJ16: 0 | AK16: 0 | AL16: 0 | AM16: 0 | AN16: 0 | AO16: 0 | AP16: 0 | AQ16: 0 | AR16: 0 | AS16: 0 | AT16: 0 | AU16: 0 | AV16: 0 | AW16: 0 | AX16: 0 | AY16: 0 | AZ16: 0 | BA16: 0 | BB16: 0
A17: Other depository corporations | B17: 1136389 | C17: 1219871 | D17: 1233855 | E17: 1306554 | F17: 1354406 | G17: 1337946 | H17: 1379623 | I17: 1420707 | J17: 1518473 | K17: 1517104 | L17: 1570534 | M17: 1545062 | N17: 1585148 | O17: 1489579 | P17: 1526017 | Q17: 1468339 | R17: 1464342 | S17: 1533122 | T17: 1663764 | U17: 1576772 | V17: 1669698 | W17: 1733448 | X17: 1683752 | Y17: 1802302 | Z17: 1861298 | AA17: 1943799 | AB17: 2092528 | AC17: 2264869 | AD17: 2407513 | AE17: 2482443 | AF17: 2426205 | AG17: 2524372 | AH17: 2743925 | AI17: 2831494 | AJ17: 2983903 | AK17: 3061149 | AL17: 3229968 | AM17: 3118855 | AN17: 2911401 | AO17: 2846795 | AP17: 2872688 | AQ17: 2977694 | AR17: 3040516 | AS17: 3046477 | AT17: 3041046 | AU17: 3155764 | AV17: 3293820 | AW17: 3349328 | AX17: 3382139 | AY17: 3208091 | AZ17: 3206508 | BA17: 3259097 | BB17: 3232770
A18: Short-term | B18: 0 | C18: 0 | D18: 0 | E18: 0 | F18: 0 | G18: 0 | H18: 0 | I18: 0 | J18: 0 | K18: 0 | L18: 0 | M18: 0 | N18: 0 | O18: 0 | P18: 10 | Q18: 316 | R18: 956 | S18: 58233 | T18: 81500 | U18: 12860 | V18: 37360 | W18: 34587 | X18: 32687 | Y18: 28946 | Z18: 10288 | AA18: 13271 | AB18: 69855 | AC18: 151177 | AD18: 167664 | AE18: 167411 | AF18: 160701 | AG18: 133026 | AH18: 124089 | AI18: 96165 | AJ18: 67659 | AK18: 66474 | AL18: 90960 | AM18: 72307 | AN18: 66508 | AO18: 67388 | AP18: 28684 | AQ18: 67926 | AR18: 74486 | AS18: 169336 | AT18: 125709 | AU18: 203699 | AV18: 157076 | AW18: 146855 | AX18: 112855 | AY18: 101459 | AZ18: 80668 | BA18: 96079 | BB18: 124101
A19: Long-term | B19: 1136389 | C19: 1219871 | D19: 1233855 | E19: 1306554 | F19: 1354406 | G19: 1337946 | H19: 1379623 | I19: 1420707 | J19: 1518473 | K19: 1517104 | L19: 1570534 | M19: 1545062 | N19: 1585148 | O19: 1489579 | P19: 1526008 | Q19: 1468023 | R19: 1463386 | S19: 1474889 | T19: 1582264 | U19: 1563912 | V19: 1632338 | W19: 1698862 | X19: 1651065 | Y19: 1773356 | Z19: 1851011 | AA19: 1930528 | AB19: 2022672 | AC19: 2113692 | AD19: 2239850 | AE19: 2315032 | AF19: 2265505 | AG19: 2391347 | AH19: 2619837 | AI19: 2735329 | AJ19: 2916244 | AK19: 2994675 | AL19: 3139008 | AM19: 3046548 | AN19: 2844893 | AO19: 2779406 | AP19: 2844003 | AQ19: 2909768 | AR19: 2966030 | AS19: 2877141 | AT19: 2915338 | AU19: 2952064 | AV19: 3136744 | AW19: 3202473 | AX19: 3269283 | AY19: 3106632 | AZ19: 3125840 | BA19: 3163018 | BB19: 3108669
A20: Long term, with a remaining maturity up to and including 1 year | Z20: 151691 | AA20: 190111 | AB20: 255214 | AC20: 242852 | AD20: 281021 | AE20: 329973 | AF20: 338530 | AG20: 456594 | AH20: 454808 | AI20: 499447 | AJ20: 505469 | AK20: 432210 | AL20: 451371 | AM20: 419510 | AN20: 445176 | AO20: 497395 | AP20: 609957 | AQ20: 590743 | AR20: 596109 | AS20: 580480 | AT20: 569123 | AU20: 671192 | AV20: 578336 | AW20: 595246 | AX20: 530780 | AY20: 395702 | AZ20: 585002 | BA20: 565283 | BB20: 591706
A21: Long term, with a remaining maturity more than 1 year | Z21: 1699320 | AA21: 1740417 | AB21: 1767459 | AC21: 1870840 | AD21: 1958828 | AE21: 1985059 | AF21: 1926975 | AG21: 1934752 | AH21: 2165028 | AI21: 2235882 | AJ21: 2410775 | AK21: 2562465 | AL21: 2687637 | AM21: 2627038 | AN21: 2399718 | AO21: 2282011 | AP21: 2234047 | AQ21: 2319025 | AR21: 2369921 | AS21: 2296661 | AT21: 2346215 | AU21: 2280873 | AV21: 2558408 | AW21: 2607226 | AX21: 2738504 | AY21: 2710930 | AZ21: 2540837 | BA21: 2597736 | BB21: 2516962
A22: Insurance corporations | B22: 15000 | C22: 15000 | D22: 18000 | E22: 18000 | F22: 18000 | G22: 18000 | H22: 18000 | I22: 18000 | J22: 13000 | K22: 13000 | L22: 13000 | M22: 13000 | N22: 13000 | O22: 13000 | P22: 13000 | Q22: 13000 | R22: 13000 | S22: 13000 | T22: 17000 | U22: 12000 | V22: 7000 | W22: 7000 | X22: 7000 | Y22: 7000 | Z22: 7000 | AA22: 7000 | AB22: 7000 | AC22: 4000 | AD22: 7000 | AE22: 7343 | AF22: 7157 | AG22: 7329 | AH22: 7161 | AI22: 7329 | AJ22: 7127 | AK22: 7266 | AL22: 4068 | AM22: 4137 | AN22: 0 | AO22: 0 | AP22: 0 | AQ22: 0 | AR22: 0 | AS22: 0 | AT22: 0 | AU22: 0 | AV22: 0 | AW22: 0 | AX22: 0 | AY22: 0 | AZ22: 0 | BA22: 0 | BB22: 0
A23: Short-term | B23: 0 | C23: 0 | D23: 0 | E23: 0 | F23: 0 | G23: 0 | H23: 0 | I23: 0 | J23: 0 | K23: 0 | L23: 0 | M23: 0 | N23: 0 | O23: 0 | P23: 0 | Q23: 0 | R23: 0 | S23: 0 | T23: 0 | U23: 0 | V23: 0 | W23: 0 | X23: 0 | Y23: 0 | Z23: 0 | AA23: 0 | AB23: 0 | AC23: 0 | AD23: 0 | AE23: 0 | AF23: 0 | AG23: 0 | AH23: 0 | AI23: 0 | AJ23: 0 | AK23: 0 | AL23: 0 | AM23: 0 | AN23: 0 | AO23: 0 | AP23: 0 | AQ23: 0 | AR23: 0 | AS23: 0 | AT23: 0 | AU23: 0 | AV23: 0 | AW23: 0 | AX23: 0 | AY23: 0 | AZ23: 0 | BA23: 0 | BB23: 0
A24: Long-term | B24: 15000 | C24: 15000 | D24: 18000 | E24: 18000 | F24: 18000 | G24: 18000 | H24: 18000 | I24: 18000 | J24: 13000 | K24: 13000 | L24: 13000 | M24: 13000 | N24: 13000 | O24: 13000 | P24: 13000 | Q24: 13000 | R24: 13000 | S24: 13000 | T24: 17000 | U24: 12000 | V24: 7000 | W24: 7000 | X24: 7000 | Y24: 7000 | Z24: 7000 | AA24: 7000 | AB24: 7000 | AC24: 4000 | AD24: 7000 | AE24: 7343 | AF24: 7157 | AG24: 7329 | AH24: 7161 | AI24: 7329 | AJ24: 7127 | AK24: 7266 | AL24: 4068 | AM24: 4137 | AN24: 0 | AO24: 0 | AP24: 0 | AQ24: 0 | AR24: 0 | AS24: 0 | AT24: 0 | AU24: 0 | AV24: 0 | AW24: 0 | AX24: 0 | AY24: 0 | AZ24: 0 | BA24: 0 | BB24: 0
A25: Long term, with a remaining maturity up to and including 1 year | Z25: 0 | AA25: 0 | AB25: 0 | AC25: 0 | AD25: 0 | AE25: 0 | AF25: 0 | AG25: 0 | AH25: 0 | AI25: 0 | AJ25: 4066 | AK25: 4137 | AL25: 4068 | AM25: 4137 | AN25: 0 | AO25: 0 | AP25: 0 | AQ25: 0 | AR25: 0 | AS25: 0 | AT25: 0 | AU25: 0 | AV25: 0 | AW25: 0 | AX25: 0 | AY25: 0 | AZ25: 0 | BA25: 0 | BB25: 0
A26: Long term, with a remaining maturity more than 1 year | Z26: 7000 | AA26: 7000 | AB26: 7000 | AC26: 4000 | AD26: 7000 | AE26: 7343 | AF26: 7157 | AG26: 7329 | AH26: 7161 | AI26: 7329 | AJ26: 3061 | AK26: 3129 | AL26: 0 | AM26: 0 | AN26: 0 | AO26: 0 | AP26: 0 | AQ26: 0 | AR26: 0 | AS26: 0 | AT26: 0 | AU26: 0 | AV26: 0 | AW26: 0 | AX26: 0 | AY26: 0 | AZ26: 0 | BA26: 0 | BB26: 0
A27: Other financial corporations | B27: 1045141 | C27: 1137851 | D27: 1174287 | E27: 1264231 | F27: 1318061 | G27: 1477360 | H27: 1504747 | I27: 1696463 | J27: 1860427 | K27: 1879853 | L27: 1914413 | M27: 2042641 | N27: 2144131 | O27: 2161609 | P27: 2279290 | Q27: 2323136 | R27: 2389775 | S27: 2442657 | T27: 2618180 | U27: 2706812 | V27: 2702325 | W27: 2780284 | X27: 2778325 | Y27: 2693537 | Z27: 2695018 | AA27: 2776390 | AB27: 2886916 | AC27: 2858992 | AD27: 3105320 | AE27: 3267800 | AF27: 3234397 | AG27: 3351864 | AH27: 3784229 | AI27: 3700135 | AJ27: 3566143 | AK27: 3696683 | AL27: 4171144 | AM27: 4111166 | AN27: 4062242 | AO27: 4533378 | AP27: 6094704 | AQ27: 6787469 | AR27: 7420943 | AS27: 8754756 | AT27: 10005320 | AU27: 10336511 | AV27: 10522935 | AW27: 11520139 | AX27: 13213373 | AY27: 13065965 | AZ27: 13282786 | BA27: 14232954 | BB27: 15063823
A28: Short-term | B28: 0 | C28: 0 | D28: 0 | E28: 0 | F28: 0 | G28: 873 | H28: 873 | I28: 873 | J28: 0 | K28: 0 | L28: 0 | M28: 0 | N28: 0 | O28: 0 | P28: 0 | Q28: 0 | R28: 30 | S28: 80 | T28: 108 | U28: 138 | V28: 148 | W28: 50759 | X28: 40430 | Y28: 14062 | Z28: 8490 | AA28: 20926 | AB28: 41838 | AC28: 25272 | AD28: 8142 | AE28: 1632 | AF28: 2454 | AG28: 6399 | AH28: 8332 | AI28: 14784 | AJ28: 29394 | AK28: 21063 | AL28: 56867 | AM28: 62344 | AN28: 63029 | AO28: 113361 | AP28: 89672 | AQ28: 83953 | AR28: 78293 | AS28: 109835 | AT28: 126842 | AU28: 139768 | AV28: 217461 | AW28: 163646 | AX28: 277729 | AY28: 331171 | AZ28: 351154 | BA28: 400632 | BB28: 330915
A29: Long-term | B29: 1045141 | C29: 1137851 | D29: 1174287 | E29: 1264231 | F29: 1318061 | G29: 1476487 | H29: 1503874 | I29: 1695590 | J29: 1860427 | K29: 1879853 | L29: 1914413 | M29: 2042641 | N29: 2144131 | O29: 2161609 | P29: 2279290 | Q29: 2323136 | R29: 2389745 | S29: 2442577 | T29: 2618071 | U29: 2706673 | V29: 2702176 | W29: 2729525 | X29: 2737895 | Y29: 2679475 | Z29: 2686528 | AA29: 2755464 | AB29: 2845078 | AC29: 2833720 | AD29: 3097178 | AE29: 3266168 | AF29: 3231942 | AG29: 3345465 | AH29: 3775897 | AI29: 3685351 | AJ29: 3536750 | AK29: 3675620 | AL29: 4114277 | AM29: 4048822 | AN29: 3999213 | AO29: 4420016 | AP29: 6005032 | AQ29: 6703517 | AR29: 7342650 | AS29: 8644921 | AT29: 9878479 | AU29: 10196743 | AV29: 10305475 | AW29: 11356493 | AX29: 12935644 | AY29: 12734795 | AZ29: 12931632 | BA29: 13832322 | BB29: 14732908
A30: Long term, with a remaining maturity up to and including 1 year | Z30: 113608 | AA30: 109746 | AB30: 153350 | AC30: 146871 | AD30: 173871 | AE30: 243887 | AF30: 539083 | AG30: 612969 | AH30: 566943 | AI30: 536633 | AJ30: 230278 | AK30: 152532 | AL30: 194369 | AM30: 192058 | AN30: 164135 | AO30: 198101 | AP30: 206753 | AQ30: 254680 | AR30: 296754 | AS30: 424006 | AT30: 441890 | AU30: 536991 | AV30: 690654 | AW30: 822063 | AX30: 1413237 | AY30: 1324575 | AZ30: 1213840 | BA30: 1601036 | BB30: 1142072
A31: Long term, with a remaining maturity more than 1 year | Z31: 2572921 | AA31: 2645718 | AB31: 2691728 | AC31: 2686850 | AD31: 2923308 | AE31: 3022282 | AF31: 2692860 | AG31: 2732497 | AH31: 3208954 | AI31: 3148718 | AJ31: 3306472 | AK31: 3523088 | AL31: 3919907 | AM31: 3856764 | AN31: 3835078 | AO31: 4221915 | AP31: 5798279 | AQ31: 6448837 | AR31: 7045896 | AS31: 8220915 | AT31: 9436589 | AU31: 9659753 | AV31: 9614820 | AW31: 10534430 | AX31: 11522407 | AY31: 11410219 | AZ31: 11717792 | BA31: 12231287 | BB31: 13590835
A32: General government | B32: 4414257 | C32: 4233274 | D32: 4415712 | E32: 4569162 | F32: 4859751 | G32: 4857140 | H32: 4896539 | I32: 4892619 | J32: 5892743 | K32: 5791168 | L32: 5864372 | M32: 5829353 | N32: 6012760 | O32: 6117163 | P32: 6258021 | Q32: 6272802 | R32: 6586035 | S32: 6947083 | T32: 7116831 | U32: 7572861 | V32: 7820146 | W32: 7879971 | X32: 8135309 | Y32: 8261275 | Z32: 8462574 | AA32: 8804502 | AB32: 9456789 | AC32: 9945470 | AD32: 10146562 | AE32: 10571931 | AF32: 11480294 | AG32: 12796005 | AH32: 15325835 | AI32: 16012522 | AJ32: 16847854 | AK32: 17352866 | AL32: 17081503 | AM32: 17205947 | AN32: 17255435 | AO32: 16828191 | AP32: 19559128 | AQ32: 20118883 | AR32: 21002129 | AS32: 21322717 | AT32: 21852925 | AU32: 22333044 | AV32: 22436962 | AW32: 22758722 | AX32: 26946518 | AY32: 27605549 | AZ32: 28982557 | BA32: 30200873 | BB32: 33429770
A33: Short-term | B33: 0 | C33: 0 | D33: 0 | E33: 0 | F33: 0 | G33: 0 | H33: 0 | I33: 0 | J33: 0 | K33: 0 | L33: 0 | M33: 0 | N33: 0 | O33: 0 | P33: 0 | Q33: 0 | R33: 0 | S33: 0 | T33: 0 | U33: 0 | V33: 0 | W33: 0 | X33: 0 | Y33: 0 | Z33: 3000 | AA33: 3000 | AB33: 3000 | AC33: 3000 | AD33: 0 | AE33: 0 | AF33: 0 | AG33: 0 | AH33: 0 | AI33: 0 | AJ33: 0 | AK33: 0 | AL33: 0 | AM33: 5416 | AN33: 5570 | AO33: 5417 | AP33: 5574 | AQ33: 0 | AR33: 0 | AS33: 15052 | AT33: 60200 | AU33: 59928 | AV33: 6363 | AW33: 4363 | AX33: 0 | AY33: 0 | AZ33: 0 | BA33: 0 | BB33: 0
A34: Long-term | B34: 4414257 | C34: 4233274 | D34: 4415712 | E34: 4569162 | F34: 4859751 | G34: 4857140 | H34: 4896539 | I34: 4892619 | J34: 5892743 | K34: 5791168 | L34: 5864372 | M34: 5829353 | N34: 6012760 | O34: 6117163 | P34: 6258021 | Q34: 6272802 | R34: 6586035 | S34: 6947083 | T34: 7116831 | U34: 7572861 | V34: 7820146 | W34: 7879971 | X34: 8135309 | Y34: 8261275 | Z34: 8459574 | AA34: 8801502 | AB34: 9453789 | AC34: 9942470 | AD34: 10146562 | AE34: 10571931 | AF34: 11480294 | AG34: 12796005 | AH34: 15325835 | AI34: 16012522 | AJ34: 16847854 | AK34: 17352866 | AL34: 17081503 | AM34: 17200532 | AN34: 17249865 | AO34: 16822774 | AP34: 19553554 | AQ34: 20118883 | AR34: 21002129 | AS34: 21307665 | AT34: 21792726 | AU34: 22273116 | AV34: 22430599 | AW34: 22754359 | AX34: 26946518 | AY34: 27605549 | AZ34: 28982557 | BA34: 30200873 | BB34: 33429770
A35: Long term, with a remaining maturity up to and including 1 year | Z35: 728232 | AA35: 818588 | AB35: 807334 | AC35: 824086 | AD35: 565997 | AE35: 413026 | AF35: 310002 | AG35: 583059 | AH35: 1037677 | AI35: 948081 | AJ35: 809296 | AK35: 977403 | AL35: 1111038 | AM35: 1270470 | AN35: 1282520 | AO35: 1331627 | AP35: 901307 | AQ35: 1129081 | AR35: 1471083 | AS35: 1374332 | AT35: 1584551 | AU35: 1624414 | AV35: 1309235 | AW35: 1425173 | AX35: 1514274 | AY35: 1643947 | AZ35: 1848192 | BA35: 1793077 | BB35: 1697711
A36: Long term, with a remaining maturity more than 1 year | Z36: 7731342 | AA36: 7982915 | AB36: 8646455 | AC36: 9118384 | AD36: 9580565 | AE36: 10158905 | AF36: 11170292 | AG36: 12212945 | AH36: 14288158 | AI36: 15064441 | AJ36: 16038558 | AK36: 16375463 | AL36: 15970465 | AM36: 15930062 | AN36: 15967345 | AO36: 15491147 | AP36: 18652247 | AQ36: 18989802 | AR36: 19531046 | AS36: 19933333 | AT36: 20208174 | AU36: 20648702 | AV36: 21121364 | AW36: 21329187 | AX36: 25432244 | AY36: 25961602 | AZ36: 27134365 | BA36: 28407796 | BB36: 31732059
A37: Nonfinancial corporations | B37: 1835416 | C37: 1937148 | D37: 2001546 | E37: 2041163 | F37: 2126927 | G37: 2162627 | H37: 2159302 | I37: 2167025 | J37: 2847022 | K37: 3248706 | L37: 3412307 | M37: 3525571 | N37: 3731458 | O37: 3772805 | P37: 4072985 | Q37: 4287576 | R37: 5053436 | S37: 5151570 | T37: 5405886 | U37: 5709501 | V37: 6486115 | W37: 6598917 | X37: 6641897 | Y37: 6630854 | Z37: 6719667 | AA37: 6774317 | AB37: 6936857 | AC37: 6995819 | AD37: 7345798 | AE37: 7639022 | AF37: 7698515 | AG37: 7824063 | AH37: 8988494 | AI37: 8721208 | AJ37: 8652817 | AK37: 9048586 | AL37: 9301861 | AM37: 9165760 | AN37: 8843816 | AO37: 9227874 | AP37: 9427671 | AQ37: 9603681 | AR37: 9863796 | AS37: 9948864 | AT37: 10220704 | AU37: 10778411 | AV37: 10992321 | AW37: 11856339 | AX37: 13154263 | AY37: 13833531 | AZ37: 14837198 | BA37: 15886839 | BB37: 16078641
A38: Short-term | B38: 0 | C38: 2000 | D38: 2000 | E38: 2000 | F38: 2000 | G38: 0 | H38: 15000 | I38: 15000 | J38: 0 | K38: 0 | L38: 0 | M38: 0 | N38: 0 | O38: 0 | P38: 0 | Q38: 100 | R38: 100 | S38: 100 | T38: 130 | U38: 60 | V38: 10060 | W38: 11770 | X38: 10990 | Y38: 10960 | Z38: 210 | AA38: 200 | AB38: 0 | AC38: 50 | AD38: 90 | AE38: 192 | AF38: 191 | AG38: 242 | AH38: 464 | AI38: 464 | AJ38: 404 | AK38: 214 | AL38: 6677 | AM38: 7539 | AN38: 4604 | AO38: 5186 | AP38: 39915 | AQ38: 44240 | AR38: 2188 | AS38: 2653 | AT38: 34891 | AU38: 58031 | AV38: 66034 | AW38: 33997 | AX38: 20473 | AY38: 28145 | AZ38: 55597 | BA38: 57195 | BB38: 37909
A39: Long-term | B39: 1835416 | C39: 1935148 | D39: 1999546 | E39: 2039163 | F39: 2124927 | G39: 2162627 | H39: 2144302 | I39: 2152025 | J39: 2847022 | K39: 3248706 | L39: 3412307 | M39: 3525571 | N39: 3731458 | O39: 3772805 | P39: 4072985 | Q39: 4287476 | R39: 5053336 | S39: 5151470 | T39: 5405756 | U39: 5709441 | V39: 6476055 | W39: 6587147 | X39: 6630907 | Y39: 6619894 | Z39: 6719457 | AA39: 6774117 | AB39: 6936857 | AC39: 6995769 | AD39: 7345708 | AE39: 7638831 | AF39: 7698324 | AG39: 7823821 | AH39: 8988030 | AI39: 8720744 | AJ39: 8652413 | AK39: 9048372 | AL39: 9295185 | AM39: 9158221 | AN39: 8839212 | AO39: 9222688 | AP39: 9387756 | AQ39: 9559442 | AR39: 9861608 | AS39: 9946211 | AT39: 10185814 | AU39: 10720380 | AV39: 10926286 | AW39: 11822342 | AX39: 13133789 | AY39: 13805386 | AZ39: 14781601 | BA39: 15829644 | BB39: 16040732
A40: Long term, with a remaining maturity up to and including 1 year | Z40: 219196 | AA40: 283075 | AB40: 262721 | AC40: 202947 | AD40: 727370 | AE40: 1159490 | AF40: 1187476 | AG40: 1186910 | AH40: 710306 | AI40: 329491 | AJ40: 365457 | AK40: 404112 | AL40: 500862 | AM40: 604841 | AN40: 656252 | AO40: 617243 | AP40: 605380 | AQ40: 593232 | AR40: 512410 | AS40: 586007 | AT40: 837139 | AU40: 881557 | AV40: 978794 | AW40: 972190 | AX40: 1065558 | AY40: 1064401 | AZ40: 1415759 | BA40: 1777579 | BB40: 2428478
A41: Long term, with a remaining maturity more than 1 year | Z41: 6500261 | AA41: 6491042 | AB41: 6674136 | AC41: 6792822 | AD41: 6618338 | AE41: 6479340 | AF41: 6510848 | AG41: 6636912 | AH41: 8277724 | AI41: 8391253 | AJ41: 8286956 | AK41: 8644259 | AL41: 8794323 | AM41: 8553380 | AN41: 8182961 | AO41: 8605445 | AP41: 8782376 | AQ41: 8966209 | AR41: 9349198 | AS41: 9360204 | AT41: 9348674 | AU41: 9838824 | AV41: 9947492 | AW41: 10850152 | AX41: 12068232 | AY41: 12740985 | AZ41: 13365842 | BA41: 14052065 | BB41: 13612254
...

Sheet Month (nominal value)
A2: Amount outstanding of debt securities issued in domestic market at nominal value | EL2: =EL125-'Month (market value)'!EK125 -> 34396 | EN2: =EN125-'Month (market value)'!EM125 -> 32840 | EP2: =EP125-'Month (market value)'!EO125 -> -17434 | ER2: =ER125-'Month (market value)'!EQ125 -> 51370 | ET2: =ET125-'Month (market value)'!ES125 -> -8605 | EV2: =EV125-'Month (market value)'!EU125 -> -72927
A3: (on date) | EL3: =3000*12 -> 36000 | EN3: =2750*12 -> 33000 | EP3: =2000*13 -> 26000 | ER3: =1250*13 -> 16250 | ET3: =1000*15 -> 15000
A4: Millions of Rubles | EL4: july | EN4: august | EP4: september | ER4: october | ET4: november
B5: 41275 | C5: 41306 | D5: 41334 | E5: 41365 | F5: 41395 | G5: 41426 | H5: 41456 | I5: 41487 | J5: 41518 | K5: 41548 | L5: 41579 | M5: 41609 | N5: 41640 | O5: 41671 | P5: 41699 | Q5: 41730 | R5: 41760 | S5: 41791 | T5: 41821 | U5: 41852 | V5: 41883 | W5: 41913 | X5: 41944 | Y5: 41974 | Z5: 42005 | AA5: 42036 | AB5: 42064 | AC5: 42095 | AD5: 42125 | AE5: 42156 | AF5: 42186 | AG5: 42217 | AH5: 42248 | AI5: 42278 | AJ5: 42309 | AK5: 42339 | AL5: 42370 | AM5: 42401 | AN5: 42430 | AO5: 42461 | AP5: 42491 | AQ5: 42522 | AR5: 42552 | AS5: 42583 | AT5: 42614 | AU5: 42644 | AV5: 42675 | AW5: 42705 | AX5: 42736 | AY5: 42767 | AZ5: 42795 | BA5: 42826 | BB5: 42856 | BC5: 42887 | BD5: 42917 | BE5: 42948 | BF5: 42979 | BG5: 43009 | BH5: 43040 | BI5: 43070 | BJ5: 43101 | BK5: 43132 | BL5: 43160 | BM5: 43191 | BN5: 43221 | BO5: 43252 | BP5: 43282 | BQ5: 43313 | BR5: 43344 | BS5: 43374 | BT5: 43405 | BU5: 43435 | BV5: 01.01.2019* | BW5: 43497 | BX5: 43525 | BY5: 43556 | BZ5: 43586 | CA5: 43617 | CB5: 43647 | CC5: 43678 | CD5: 43709 | CE5: 43739 | CF5: 43770 | CG5: 43800 | CH5: 43831 | CI5: 43862 | CJ5: 43891 | CK5: 43922 | CL5: 43952 | CM5: 43983 | CN5: 44013 | CO5: 44044 | CP5: 44075 | CQ5: 44105 | CR5: 44136 | CS5: 44166 | CT5: 44197 | CU5: 44228 | CV5: 44256 | CW5: 44287 | CX5: 44317 | CY5: 44348 | CZ5: 44378 | DA5: 44409 | DB5: 44440 | DC5: 44470 | DD5: 44501 | DE5: 44531 | DF5: 44562 | DG5: 44593 | DH5: 44621 | DI5: 44652 | DJ5: 44682 | DK5: 44713 | DL5: 44743 | DM5: 44774 | DN5: 44805 | DO5: 44835 | DP5: 44866 | DQ5: 44896 | DR5: 44927 | DS5: 44958 | DT5: 44986 | DU5: 45017 | DV5: 45047 | DW5: 45078 | DX5: 45108 | DY5: 45139 | DZ5: 45170 | EA5: 45200 | EB5: 45231 | EC5: 45261 | ED5: 45292 | EE5: 45323 | EF5: 45352 | EG5: 45383 | EH5: 45413 | EI5: 45444 | EK5: 45474 | EM5: 45505 | EO5: 45536 | EQ5: 45566 | ES5: 45597 | EU5: 45627 | EW5: 45658 | EX5: 45689 | EY5: 45717 | EZ5: 45748 | FA5: 45778 | FB5: 45809 | FC5: 45839 | FD5: 45870 | FE5: 45901 | FF5: 45931 | FG5: 45962 | FH5: 45992 | FI5: 46023 | FJ5: 46054
A6: Amount outstanding of debt securities - total
A7: Total | B7: 8516504 | C7: 8394063 | D7: 8520762 | E7: 8613445 | F7: 8772740 | G7: 8808909 | H7: 8913700 | I7: 8998623 | J7: 9096183 | K7: 9286909 | L7: 9529247 | M7: 9709743 | N7: 9779946 | O7: 9979647 | P7: 10062892 | Q7: 9955872 | R7: 9946395 | S7: 9993195 | T7: 10060011 | U7: 10282437 | V7: 10220938 | W7: 10296614 | X7: 10462618 | Y7: 10352206 | Z7: 12237465 | AA7: 12720721 | AB7: 12709787 | AC7: 12555631 | AD7: 12697248 | AE7: 12898492 | AF7: 12883426 | AG7: 13212770 | AH7: 13029085 | AI7: 13064426 | AJ7: 13258483 | AK7: 13383043 | AL7: 13600298 | AM7: 13591577 | AN7: 13475771 | AO7: 13669956 | AP7: 14059267 | AQ7: 14137996 | AR7: 14264113 | AS7: 14379269 | AT7: 14326499 | AU7: 14479652 | AV7: 14587678 | AW7: 14801976 | AX7: 15616388 | AY7: 15790950 | AZ7: 15950824 | BA7: 16197232 | BB7: 16297946 | BC7: 16737307 | BD7: 16941460 | BE7: 17318481 | BF7: 17731185 | BG7: 17847276 | BH7: 18344153 | BI7: 18452453 | BJ7: 19144405 | BK7: 19333072 | BL7: 19819833 | BM7: 20235101 | BN7: 20261759 | BO7: 20578482 | BP7: 20465232 | BQ7: 21013438 | BR7: 21050816 | BS7: 20991227 | BT7: 21015398 | BU7: 21317025 | BV7: 21227588 | BW7: 21504765 | BX7: 21629561 | BY7: 21908808 | BZ7: 22583291 | CA7: 22911681 | CB7: 23182889 | CC7: 23487811 | CD7: 23239118 | CE7: 22978950 | CF7: 23671204 | CG7: 24283955 | CH7: 25070699 | CI7: 25137964 | CJ7: 25854835 | CK7: 25633288 | CL7: 25915972 | CM7: 25669640 | CN7: 25715007 | CO7: 26218073 | CP7: 26646547 | CQ7: 27474233 | CR7: 28935825 | CS7: 30816462 | CT7: 31557716 | CU7: 31117583 | CV7: 31357693 | CW7: 32049396 | CX7: 32449404 | CY7: 32759502 | CZ7: 32805309 | DA7: 33188027 | DB7: 33509501 | DC7: 33891217 | DD7: 34008227 | DE7: 34016370 | DF7: 33895352 | DG7: 33906453 | DH7: 33939639 | DI7: 33712879 | DJ7: 33314475 | DK7: 33394038 | DL7: 33186753 | DM7: 33004490 | DN7: 33386060 | DO7: 33644123 | DP7: 34276564 | DQ7: 35699230 | DR7: 38196529 | DS7: 38362718 | DT7: 39031021 | DU7: 39686752 | DV7: 40416690 | DW7: 40699497 | DX7: 41532038 | DY7: 42488617 | DZ7: 42948067 | EA7: 43293476 | EB7: 43266614 | EC7: 43504703 | ED7: 45350008 | EE7: 45602421 | EF7: 46062237 | EG7: 46859535 | EH7: 46866370 | EI7: 47237090 | EJ7: =EK7-EI7 -> 248779 | EK7: 47485869 | EL7: =EM7-EK7 -> 139110 | EM7: 47624979 | EN7: =EO7-EM7 -> 1014599 | EO7: 48639578 | EP7: =EQ7-EO7 -> 1094825 | EQ7: 49734403 | ER7: =ES7-EQ7 -> 400112 | ES7: 50134515 | ET7: =EU7-ES7 -> 1106463 | EU7: 51240978 | EV7: =EW7-EU7 -> 5713648 | EW7: 56954626 | EX7: 56922877 | EY7: 57180927 | EZ7: 57945806 | FA7: 59046726 | FB7: 59629599 | FC7: 60519471 | FD7: 61816617 | FE7: 62912239 | FF7: 63791443 | FG7: 64843154 | FH7: 66485081 | FI7: 68005551 | FJ7: 67933097
A8: Short-term | B8: 13000 | C8: 13000 | D8: 15000 | E8: 15000 | F8: 15000 | G8: 15000 | H8: 15000 | I8: 15000 | J8: 15000 | K8: 15000 | L8: 2000 | M8: 2000 | N8: 2000 | O8: 0 | P8: 0 | Q8: 873 | R8: 873 | S8: 15873 | T8: 15873 | U8: 15873 | V8: 15873 | W8: 15873 | X8: 30873 | Y8: 30873 | Z8: 0 | AA8: 0 | AB8: 0 | AC8: 0 | AD8: 0 | AE8: 0 | AF8: 0 | AG8: 0 | AH8: 0 | AI8: 0 | AJ8: 0 | AK8: 0 | AL8: 0 | AM8: 3000 | AN8: 3000 | AO8: 3000 | AP8: 3000 | AQ8: 3000 | AR8: 3010 | AS8: 3010 | AT8: 3334 | AU8: 3416 | AV8: 8317 | AW8: 33869 | AX8: 4086 | AY8: 41162 | AZ8: 46406 | BA8: 71413 | BB8: 20166 | BC8: 60366 | BD8: 81738 | BE8: 54661 | BF8: 216553 | BG8: 165588 | BH8: 381161 | BI8: 353133 | BJ8: 399890 | BK8: 649436 | BL8: 869853 | BM8: 1225796 | BN8: 1139534 | BO8: 1377555 | BP8: 1196256 | BQ8: 1548903 | BR8: 1514004 | BS8: 1540427 | BT8: 1542713 | BU8: 1685646 | BV8: 1396218 | BW8: 1552566 | BX8: 1581207 | BY8: 1537398 | BZ8: 1578063 | CA8: 1696418 | CB8: 1814693 | CC8: 1642160 | CD8: 1330307 | CE8: 981499 | CF8: 1273409 | CG8: 1659789 | CH8: 2115601 | CI8: 2254081 | CJ8: 2091353 | CK8: 1713463 | CL8: 1678696 | CM8: 1249139 | CN8: 871475 | CO8: 869945 | CP8: 978923 | CQ8: 958202 | CR8: 827466 | CS8: 723910 | CT8: 707112 | CU8: 681343 | CV8: 669477 | CW8: 756482 | CX8: 761270 | CY8: 772167 | CZ8: 723835 | DA8: 684598 | DB8: 666657 | DC8: 691104 | DD8: 576184 | DE8: 311498 | DF8: 154503 | DG8: 158785 | DH8: 157029 | DI8: 147605 | DJ8: 142873 | DK8: 148413 | DL8: 139711 | DM8: 177383 | DN8: 207044 | DO8: 234748 | DP8: 234945 | DQ8: 175943 | DR8: 208173 | DS8: 225651 | DT8: 163986 | DU8: 196119 | DV8: 105534 | DW8: 142092 | DX8: 154967 | DY8: 200743 | DZ8: 208588 | EA8: 296876 | EB8: 344800 | EC8: 312728 | ED8: 347640 | EE8: 459259 | EF8: 365623 | EG8: 461426 | EH8: 425034 | EI8: 466260 | EJ8: =EK8-EI8 -> -19327 | EK8: 446933 | EL8: =EM8-EK8 -> -56224 | EM8: 390709 | EN8: =EO8-EM8 -> -82353 | EO8: 308356 | EP8: =EQ8-EO8 -> 40506 | EQ8: 348862 | ER8: =ES8-EQ8 -> -111788 | ES8: 237074 | ET8: =EU8-ES8 -> -21880 | EU8: 215194 | EV8: =EW8-EU8 -> 195864 | EW8: 411058 | EX8: 399510 | EY8: 441507 | EZ8: 460775 | FA8: 480984 | FB8: 514392 | FC8: 487419 | FD8: 557671 | FE8: 601158 | FF8: 553905 | FG8: 574254 | FH8: 490813 | FI8: 492925 | FJ8: 496816
A9: Long-term | B9: 8503504 | C9: 8381063 | D9: 8505762 | E9: 8598445 | F9: 8757740 | G9: 8793909 | H9: 8898700 | I9: 8983623 | J9: 9081183 | K9: 9271909 | L9: 9527247 | M9: 9707743 | N9: 9777946 | O9: 9979647 | P9: 10062892 | Q9: 9954999 | R9: 9945522 | S9: 9977322 | T9: 10044138 | U9: 10266564 | V9: 10205065 | W9: 10280741 | X9: 10431745 | Y9: 10321333 | Z9: 12237465 | AA9: 12720721 | AB9: 12709787 | AC9: 12555631 | AD9: 12697248 | AE9: 12898492 | AF9: 12883426 | AG9: 13212770 | AH9: 13029085 | AI9: 13064426 | AJ9: 13258483 | AK9: 13383043 | AL9: 13600298 | AM9: 13588577 | AN9: 13472771 | AO9: 13666956 | AP9: 14056267 | AQ9: 14134996 | AR9: 14261103 | AS9: 14376259 | AT9: 14323164 | AU9: 14476237 | AV9: 14579361 | AW9: 14768107 | AX9: 15612302 | AY9: 15749788 | AZ9: 15904418 | BA9: 16125819 | BB9: 16277779 | BC9: 16676941 | BD9: 16859722 | BE9: 17263820 | BF9: 17514632 | BG9: 17681688 | BH9: 17962992 | BI9: 18099320 | BJ9: 18744515 | BK9: 18683636 | BL9: 18949979 | BM9: 19009304 | BN9: 19122225 | BO9: 19200927 | BP9: 19268976 | BQ9: 19464535 | BR9: 19536811 | BS9: 19450800 | BT9: 19472685 | BU9: 19631378 | BV9: 19831370 | BW9: 19952200 | BX9: 20048354 | BY9: 20371410 | BZ9: 21005228 | CA9: 21215263 | CB9: 21368196 | CC9: 21845651 | CD9: 21908812 | CE9: 21997452 | CF9: 22397795 | CG9: 22624166 | CH9: 22955098 | CI9: 22883883 | CJ9: 23763482 | CK9: 23919825 | CL9: 24237276 | CM9: 24420500 | CN9: 24843532 | CO9: 25348128 | CP9: 25667624 | CQ9: 26516032 | CR9: 28108359 | CS9: 30092552 | CT9: 30850604 | CU9: 30436240 | CV9: 30688216 | CW9: 31292914 | CX9: 31688134 | CY9: 31987335 | CZ9: 32081473 | DA9: 32503429 | DB9: 32842844 | DC9: 33200113 | DD9: 33432044 | DE9: 33704872 | DF9: 33740849 | DG9: 33747669 | DH9: 33782610 | DI9: 33565274 | DJ9: 33171602 | DK9: 33245625 | DL9: 33047042 | DM9: 32827107 | DN9: 33179016 | DO9: 33409375 | DP9: 34041620 | DQ9: 35523287 | DR9: 37988356 | DS9: 38137067 | DT9: 38867035 | DU9: 39490634 | DV9: 40311156 | DW9: 40557405 | DX9: 41377071 | DY9: 42287874 | DZ9: 42739479 | EA9: 42996601 | EB9: 42921813 | EC9: 43191975 | ED9: 45002368 | EE9: 45143162 | EF9: 45696614 | EG9: 46398109 | EH9: 46441337 | EI9: 46770830 | EJ9: =EK9-EI9 -> 268106 | EK9: 47038936 | EL9: =EM9-EK9 -> 195334 | EM9: 47234270 | EN9: =EO9-EM9 -> 1096952 | EO9: 48331222 | EP9: =EQ9-EO9 -> 1054319 | EQ9: 49385541 | ER9: =ES9-EQ9 -> 511901 | ES9: 49897442 | ET9: =EU9-ES9 -> 1128341 | EU9: 51025783 | EV9: =EW9-EU9 -> 5517785 | EW9: 56543568 | EX9: 56523367 | EY9: 56739420 | EZ9: 57485031 | FA9: 58565742 | FB9: 59115206 | FC9: 60032052 | FD9: 61258946 | FE9: 62311081 | FF9: 63237538 | FG9: 64268900 | FH9: 65994268 | FI9: 67512626 | FJ9: 67436281
A10: Long term, with a remaining maturity up to and including 1 year | BV10: 1222726 | BW10: 1471603 | BX10: 1401547 | BY10: 1401520 | BZ10: 1380261 | CA10: 1397524 | CB10: 1478618 | CC10: 1452613 | CD10: 1443519 | CE10: 1431756 | CF10: 1417652 | CG10: 1413920 | CH10: 1768259 | CI10: 1944663 | CJ10: 2066904 | CK10: 2171695 | CL10: 2424535 | CM10: 2147878 | CN10: 2410824 | CO10: 2486836 | CP10: 2873011 | CQ10: 2860092 | CR10: 2788719 | CS10: 2868679 | CT10: 2799286 | CU10: 2425606 | CV10: 2432270 | CW10: 2338287 | CX10: 2159513 | CY10: 2158365 | CZ10: 1928866 | DA10: 2383751 | DB10: 2023759 | DC10: 1984694 | DD10: 2098127 | DE10: 2223125 | DF10: 2261708 | DG10: 2502540 | DH10: 2427553 | DI10: 2505181 | DJ10: 2393843 | DK10: 2561877 | DL10: 2582574 | DM10: 2127181 | DN10: 2677429 | DO10: 2678935 | DP10: 2872653 | DQ10: 2764426 | DR10: 2357902 | DS10: 2188717 | DT10: 2594329 | DU10: 2588135 | DV10: 2994359 | DW10: 2921397 | DX10: 2888416 | DY10: 3324555 | DZ10: 2867359 | EA10: 2976886 | EB10: 3034297 | EC10: 3340354 | ED10: 3451840 | EE10: 3750181 | EF10: 3463210 | EG10: 3738375 | EH10: 3562907 | EI10: 3580890 | EJ10: =EK10-EI10 -> 3574 | EK10: 3584464 | EL10: =EM10-EK10 -> 111105 | EM10: 3695569 | EN10: =EO10-EM10 -> 112791 | EO10: 3808360 | EP10: =EQ10-EO10 -> 44034 | EQ10: 3852394 | ER10: =ES10-EQ10 -> -162634 | ES10: 3689760 | ET10: =EU10-ES10 -> 700411 | EU10: 4390171 | EV10: =EW10-EU10 -> 169461 | EW10: 4559632 | EX10: 4177558 | EY10: 4213141 | EZ10: 4468526 | FA10: 4538167 | FB10: 4877054 | FC10: 5087753 | FD10: 4906995 | FE10: 5150665 | FF10: 5750697 | FG10: 6110808 | FH10: 5858122 | FI10: 5874459 | FJ10: 5730767
A11: Long term, with a remaining maturity more than 1 year | BV11: 18608644 | BW11: 18480597 | BX11: 18646808 | BY11: 18969891 | BZ11: 19624966 | CA11: 19817739 | CB11: 19889578 | CC11: 20393038 | CD11: 20465293 | CE11: 20565696 | CF11: 20980143 | CG11: 21210246 | CH11: 21186839 | CI11: 20939220 | CJ11: 21696577 | CK11: 21748130 | CL11: 21812741 | CM11: 22272623 | CN11: 22432709 | CO11: 22861292 | CP11: 22794613 | CQ11: 23655940 | CR11: 25319640 | CS11: 27223873 | CT11: 28051318 | CU11: 28010633 | CV11: 28255946 | CW11: 28954626 | CX11: 29528620 | CY11: 29828970 | CZ11: 30152607 | DA11: 30119678 | DB11: 30819086 | DC11: 31215419 | DD11: 31333916 | DE11: 31481747 | DF11: 31479141 | DG11: 31245129 | DH11: 31355057 | DI11: 31060093 | DJ11: 30777759 | DK11: 30683748 | DL11: 30464468 | DM11: 30699926 | DN11: 30501587 | DO11: 30730440 | DP11: 31168967 | DQ11: 32758861 | DR11: 35630455 | DS11: 35948351 | DT11: 36272706 | DU11: 36902499 | DV11: 37316797 | DW11: 37636008 | DX11: 38488655 | DY11: 38963319 | DZ11: 39872119 | EA11: 40019715 | EB11: 39887516 | EC11: 39851621 | ED11: 41550528 | EE11: 41392982 | EF11: 42233404 | EG11: 42659734 | EH11: 42878430 | EI11: 43189941 | EJ11: =EK11-EI11 -> 264531 | EK11: 43454472 | EL11: =EM11-EK11 -> 84228 | EM11: 43538700 | EN11: =EO11-EM11 -> 984162 | EO11: 44522862 | EP11: =EQ11-EO11 -> 1010285 | EQ11: 45533147 | ER11: =ES11-EQ11 -> 674535 | ES11: 46207682 | ET11: =EU11-ES11 -> 427931 | EU11: 46635613 | EV11: =EW11-EU11 -> 5348323 | EW11: 51983936 | EX11: 52345809 | EY11: 52526279 | EZ11: 53016506 | FA11: 54027575 | FB11: 54238153 | FC11: 54944299 | FD11: 56351951 | FE11: 57160416 | FF11: 57486841 | FG11: 58158092 | FH11: 60136146 | FI11: 61638167 | FJ11: 61705514
A12: Central bank | B12: 0 | C12: 0 | D12: 0 | E12: 0 | F12: 0 | G12: 0 | H12: 0 | I12: 0 | J12: 0 | K12: 0 | L12: 0 | M12: 0 | N12: 0 | O12: 0 | P12: 0 | Q12: 0 | R12: 0 | S12: 0 | T12: 0 | U12: 0 | V12: 0 | W12: 0 | X12: 0 | Y12: 0 | Z12: 0 | AA12: 0 | AB12: 0 | AC12: 0 | AD12: 0 | AE12: 0 | AF12: 0 | AG12: 0 | AH12: 0 | AI12: 0 | AJ12: 0 | AK12: 0 | AL12: 0 | AM12: 0 | AN12: 0 | AO12: 0 | AP12: 0 | AQ12: 0 | AR12: 0 | AS12: 0 | AT12: 0 | AU12: 0 | AV12: 0 | AW12: 0 | AX12: 0 | AY12: 0 | AZ12: 0 | BA12: 0 | BB12: 0 | BC12: 0 | BD12: 0 | BE12: 0 | BF12: 149530 | BG12: 149530 | BH12: 325158 | BI12: 303962 | BJ12: 352321 | BK12: 493641 | BL12: 700189 | BM12: 1128680 | BN12: 1041898 | BO12: 1205347 | BP12: 1112149 | BQ12: 1438878 | BR12: 1400158 | BS12: 1486459 | BT12: 1432800 | BU12: 1616930 | BV12: 1374230 | BW12: 1500000 | BX12: 1500000 | BY12: 1500000 | BZ12: 1500000 | CA12: 1600000 | CB12: 1700000 | CC12: 1500000 | CD12: 1200000 | CE12: 800000 | CF12: 1100000 | CG12: 1500000 | CH12: 1936705 | CI12: 2052691 | CJ12: 1873418 | CK12: 1544228 | CL12: 1519165 | CM12: 1109740 | CN12: 708128 | CO12: 707708 | CP12: 830037 | CQ12: 818535 | CR12: 698438 | CS12: 606413 | CT12: 574227 | CU12: 555056 | CV12: 545212 | CW12: 645069 | CX12: 658450 | CY12: 676913 | CZ12: 626380 | DA12: 596104 | DB12: 575867 | DC12: 603353 | DD12: 467491 | DE12: 163898 | DF12: 0 | DG12: 0 | DH12: 0 | DI12: 0 | DJ12: 0 | DK12: 0 | DL12: 0 | DM12: 0 | DN12: 0 | DO12: 0 | DP12: 0 | DQ12: 0 | DR12: 0 | DS12: 0 | DT12: 0 | DU12: 0 | DV12: 0 | DW12: 0 | DX12: 0 | DY12: 0 | DZ12: 0 | EA12: 0 | EB12: 0 | EC12: 0 | ED12: 0 | EE12: 0 | EF12: 0 | EG12: 0 | EH12: 0 | EI12: 0 | EJ12: =EK12-EI12 -> 0 | EK12: 0 | EL12: =EM12-EK12 -> 0 | EM12: 0 | EN12: =EO12-EM12 -> 0 | EO12: 0 | EP12: =EQ12-EO12 -> 0 | EQ12: 0 | ER12: =ES12-EQ12 -> 0 | ES12: 0 | ET12: =EU12-ES12 -> 0 | EU12: 0 | EV12: =EW12-EU12 -> 0 | EW12: 0 | EX12: 0 | EY12: 0 | EZ12: 0 | FA12: 0 | FB12: 0 | FC12: 0 | FD12: 0 | FE12: 0 | FF12: 0 | FG12: 0 | FH12: 0 | FI12: 0 | FJ12: 0
A13: Short-term | B13: 0 | C13: 0 | D13: 0 | E13: 0 | F13: 0 | G13: 0 | H13: 0 | I13: 0 | J13: 0 | K13: 0 | L13: 0 | M13: 0 | N13: 0 | O13: 0 | P13: 0 | Q13: 0 | R13: 0 | S13: 0 | T13: 0 | U13: 0 | V13: 0 | W13: 0 | X13: 0 | Y13: 0 | Z13: 0 | AA13: 0 | AB13: 0 | AC13: 0 | AD13: 0 | AE13: 0 | AF13: 0 | AG13: 0 | AH13: 0 | AI13: 0 | AJ13: 0 | AK13: 0 | AL13: 0 | AM13: 0 | AN13: 0 | AO13: 0 | AP13: 0 | AQ13: 0 | AR13: 0 | AS13: 0 | AT13: 0 | AU13: 0 | AV13: 0 | AW13: 0 | AX13: 0 | AY13: 0 | AZ13: 0 | BA13: 0 | BB13: 0 | BC13: 0 | BD13: 0 | BE13: 0 | BF13: 149530 | BG13: 149530 | BH13: 325158 | BI13: 303962 | BJ13: 352321 | BK13: 493641 | BL13: 700189 | BM13: 1128680 | BN13: 1041898 | BO13: 1205347 | BP13: 1112149 | BQ13: 1438878 | BR13: 1400158 | BS13: 1486459 | BT13: 1432800 | BU13: 1616930 | BV13: 1374230 | BW13: 1500000 | BX13: 1500000 | BY13: 1500000 | BZ13: 1500000 | CA13: 1600000 | CB13: 1700000 | CC13: 1500000 | CD13: 1200000 | CE13: 800000 | CF13: 1100000 | CG13: 1500000 | CH13: 1936705 | CI13: 2052691 | CJ13: 1873418 | CK13: 1544228 | CL13: 1519165 | CM13: 1109740 | CN13: 708128 | CO13: 707708 | CP13: 830037 | CQ13: 818535 | CR13: 698438 | CS13: 606413 | CT13: 574227 | CU13: 555056 | CV13: 545212 | CW13: 645069 | CX13: 658450 | CY13: 676913 | CZ13: 626380 | DA13: 596104 | DB13: 575867 | DC13: 603353 | DD13: 467491 | DE13: 163898 | DF13: 0 | DG13: 0 | DH13: 0 | DI13: 0 | DJ13: 0 | DK13: 0 | DL13: 0 | DM13: 0 | DN13: 0 | DO13: 0 | DP13: 0 | DQ13: 0 | DR13: 0 | DS13: 0 | DT13: 0 | DU13: 0 | DV13: 0 | DW13: 0 | DX13: 0 | DY13: 0 | DZ13: 0 | EA13: 0 | EB13: 0 | EC13: 0 | ED13: 0 | EE13: 0 | EF13: 0 | EG13: 0 | EH13: 0 | EI13: 0 | EJ13: =EK13-EI13 -> 0 | EK13: 0 | EL13: =EM13-EK13 -> 0 | EM13: 0 | EN13: =EO13-EM13 -> 0 | EO13: 0 | EP13: =EQ13-EO13 -> 0 | EQ13: 0 | ER13: =ES13-EQ13 -> 0 | ES13: 0 | ET13: =EU13-ES13 -> 0 | EU13: 0 | EV13: =EW13-EU13 -> 0 | EW13: 0 | EX13: 0 | EY13: 0 | EZ13: 0 | FA13: 0 | FB13: 0 | FC13: 0 | FD13: 0 | FE13: 0 | FF13: 0 | FG13: 0 | FH13: 0 | FI13: 0 | FJ13: 0
A14: Long-term | B14: 0 | C14: 0 | D14: 0 | E14: 0 | F14: 0 | G14: 0 | H14: 0 | I14: 0 | J14: 0 | K14: 0 | L14: 0 | M14: 0 | N14: 0 | O14: 0 | P14: 0 | Q14: 0 | R14: 0 | S14: 0 | T14: 0 | U14: 0 | V14: 0 | W14: 0 | X14: 0 | Y14: 0 | Z14: 0 | AA14: 0 | AB14: 0 | AC14: 0 | AD14: 0 | AE14: 0 | AF14: 0 | AG14: 0 | AH14: 0 | AI14: 0 | AJ14: 0 | AK14: 0 | AL14: 0 | AM14: 0 | AN14: 0 | AO14: 0 | AP14: 0 | AQ14: 0 | AR14: 0 | AS14: 0 | AT14: 0 | AU14: 0 | AV14: 0 | AW14: 0 | AX14: 0 | AY14: 0 | AZ14: 0 | BA14: 0 | BB14: 0 | BC14: 0 | BD14: 0 | BE14: 0 | BF14: 0 | BG14: 0 | BH14: 0 | BI14: 0 | BJ14: 0 | BK14: 0 | BL14: 0 | BM14: 0 | BN14: 0 | BO14: 0 | BP14: 0 | BQ14: 0 | BR14: 0 | BS14: 0 | BT14: 0 | BU14: 0 | BV14: 0 | BW14: 0 | BX14: 0 | BY14: 0 | BZ14: 0 | CA14: 0 | CB14: 0 | CC14: 0 | CD14: 0 | CE14: 0 | CF14: 0 | CG14: 0 | CH14: 0 | CI14: 0 | CJ14: 0 | CK14: 0 | CL14: 0 | CM14: 0 | CN14: 0 | CO14: 0 | CP14: 0 | CQ14: 0 | CR14: 0 | CS14: 0 | CT14: 0 | CU14: 0 | CV14: 0 | CW14: 0 | CX14: 0 | CY14: 0 | CZ14: 0 | DA14: 0 | DB14: 0 | DC14: 0 | DD14: 0 | DE14: 0 | DF14: 0 | DG14: 0 | DH14: 0 | DI14: 0 | DJ14: 0 | DK14: 0 | DL14: 0 | DM14: 0 | DN14: 0 | DO14: 0 | DP14: 0 | DQ14: 0 | DR14: 0 | DS14: 0 | DT14: 0 | DU14: 0 | DV14: 0 | DW14: 0 | DX14: 0 | DY14: 0 | DZ14: 0 | EA14: 0 | EB14: 0 | EC14: 0 | ED14: 0 | EE14: 0 | EF14: 0 | EG14: 0 | EH14: 0 | EI14: 0 | EJ14: =EK14-EI14 -> 0 | EK14: 0 | EL14: =EM14-EK14 -> 0 | EM14: 0 | EN14: =EO14-EM14 -> 0 | EO14: 0 | EP14: =EQ14-EO14 -> 0 | EQ14: 0 | ER14: =ES14-EQ14 -> 0 | ES14: 0 | ET14: =EU14-ES14 -> 0 | EU14: 0 | EV14: =EW14-EU14 -> 0 | EW14: 0 | EX14: 0 | EY14: 0 | EZ14: 0 | FA14: 0 | FB14: 0 | FC14: 0 | FD14: 0 | FE14: 0 | FF14: 0 | FG14: 0 | FH14: 0 | FI14: 0 | FJ14: 0
A15: Long term, with a remaining maturity up to and including 1 year | BV15: 0 | BW15: 0 | BX15: 0 | BY15: 0 | BZ15: 0 | CA15: 0 | CB15: 0 | CC15: 0 | CD15: 0 | CE15: 0 | CF15: 0 | CG15: 0 | CH15: 0 | CI15: 0 | CJ15: 0 | CK15: 0 | CL15: 0 | CM15: 0 | CN15: 0 | CO15: 0 | CP15: 0 | CQ15: 0 | CR15: 0 | CS15: 0 | CT15: 0 | CU15: 0 | CV15: 0 | CW15: 0 | CX15: 0 | CY15: 0 | CZ15: 0 | DA15: 0 | DB15: 0 | DC15: 0 | DD15: 0 | DE15: 0 | DF15: 0 | DG15: 0 | DH15: 0 | DI15: 0 | DJ15: 0 | DK15: 0 | DL15: 0 | DM15: 0 | DN15: 0 | DO15: 0 | DP15: 0 | DQ15: 0 | DR15: 0 | DS15: 0 | DT15: 0 | DU15: 0 | DV15: 0 | DW15: 0 | DX15: 0 | DY15: 0 | DZ15: 0 | EA15: 0 | EB15: 0 | EC15: 0 | ED15: 0 | EE15: 0 | EF15: 0 | EG15: 0 | EH15: 0 | EI15: 0 | EJ15: =EK15-EI15 -> 0 | EK15: 0 | EL15: =EM15-EK15 -> 0 | EM15: 0 | EN15: =EO15-EM15 -> 0 | EO15: 0 | EP15: =EQ15-EO15 -> 0 | EQ15: 0 | ER15: =ES15-EQ15 -> 0 | ES15: 0 | ET15: =EU15-ES15 -> 0 | EU15: 0 | EV15: =EW15-EU15 -> 0 | EW15: 0 | EX15: 0 | EY15: 0 | EZ15: 0 | FA15: 0 | FB15: 0 | FC15: 0 | FD15: 0 | FE15: 0 | FF15: 0 | FG15: 0 | FH15: 0 | FI15: 0 | FJ15: 0
A16: Long term, with a remaining maturity more than 1 year | BV16: 0 | BW16: 0 | BX16: 0 | BY16: 0 | BZ16: 0 | CA16: 0 | CB16: 0 | CC16: 0 | CD16: 0 | CE16: 0 | CF16: 0 | CG16: 0 | CH16: 0 | CI16: 0 | CJ16: 0 | CK16: 0 | CL16: 0 | CM16: 0 | CN16: 0 | CO16: 0 | CP16: 0 | CQ16: 0 | CR16: 0 | CS16: 0 | CT16: 0 | CU16: 0 | CV16: 0 | CW16: 0 | CX16: 0 | CY16: 0 | CZ16: 0 | DA16: 0 | DB16: 0 | DC16: 0 | DD16: 0 | DE16: 0 | DF16: 0 | DG16: 0 | DH16: 0 | DI16: 0 | DJ16: 0 | DK16: 0 | DL16: 0 | DM16: 0 | DN16: 0 | DO16: 0 | DP16: 0 | DQ16: 0 | DR16: 0 | DS16: 0 | DT16: 0 | DU16: 0 | DV16: 0 | DW16: 0 | DX16: 0 | DY16: 0 | DZ16: 0 | EA16: 0 | EB16: 0 | EC16: 0 | ED16: 0 | EE16: 0 | EF16: 0 | EG16: 0 | EH16: 0 | EI16: 0 | EJ16: =EK16-EI16 -> 0 | EK16: 0 | EL16: =EM16-EK16 -> 0 | EM16: 0 | EN16: =EO16-EM16 -> 0 | EO16: 0 | EP16: =EQ16-EO16 -> 0 | EQ16: 0 | ER16: =ES16-EQ16 -> 0 | ES16: 0 | ET16: =EU16-ES16 -> 0 | EU16: 0 | EV16: =EW16-EU16 -> 0 | EW16: 0 | EX16: 0 | EY16: 0 | EZ16: 0 | FA16: 0 | FB16: 0 | FC16: 0 | FD16: 0 | FE16: 0 | FF16: 0 | FG16: 0 | FH16: 0 | FI16: 0 | FJ16: 0
A17: Other depository corporations | B17: 1136389 | C17: 1116889 | D17: 1200371 | E17: 1219871 | F17: 1242371 | G17: 1240425 | H17: 1233855 | I17: 1253510 | J17: 1265993 | K17: 1306554 | L17: 1372134 | M17: 1355316 | N17: 1354406 | O17: 1360463 | P17: 1338840 | Q17: 1337946 | R17: 1322946 | S17: 1343505 | T17: 1379623 | U17: 1367852 | V17: 1378488 | W17: 1420707 | X17: 1458707 | Y17: 1439110 | Z17: 1518473 | AA17: 1547368 | AB17: 1534883 | AC17: 1517104 | AD17: 1517563 | AE17: 1515042 | AF17: 1570534 | AG17: 1614034 | AH17: 1555502 | AI17: 1545062 | AJ17: 1566062 | AK17: 1566652 | AL17: 1585148 | AM17: 1547348 | AN17: 1472812 | AO17: 1489579 | AP17: 1495079 | AQ17: 1521581 | AR17: 1526017 | AS17: 1510517 | AT17: 1504343 | AU17: 1468339 | AV17: 1451240 | AW17: 1463990 | AX17: 1464342 | AY17: 1511443 | AZ17: 1499301 | BA17: 1533122 | BB17: 1506934 | BC17: 1640161 | BD17: 1663764 | BE17: 1626869 | BF17: 1628607 | BG17: 1576772 | BH17: 1688126 | BI17: 1694260 | BJ17: 1669698 | BK17: 1748586 | BL17: 1752773 | BM17: 1733448 | BN17: 1712661 | BO17: 1768707 | BP17: 1683752 | BQ17: 1777405 | BR17: 1830943 | BS17: 1802302 | BT17: 1813549 | BU17: 1811980 | BV17: 1861298 | BW17: 1901619 | BX17: 1917375 | BY17: 1943799 | BZ17: 2045135 | CA17: 2098176 | CB17: 2092528 | CC17: 2190122 | CD17: 2179663 | CE17: 2264869 | CF17: 2317790 | CG17: 2321480 | CH17: 2407513 | CI17: 2430317 | CJ17: 2465280 | CK17: 2482443 | CL17: 2463052 | CM17: 2443903 | CN17: 2426205 | CO17: 2524741 | CP17: 2551612 | CQ17: 2524372 | CR17: 2573873 | CS17: 2673081 | CT17: 2743925 | CU17: 2730662 | CV17: 2814384 | CW17: 2831494 | CX17: 2878227 | CY17: 2854794 | CZ17: 2983903 | DA17: 2982709 | DB17: 3009918 | DC17: 3061149 | DD17: 3054055 | DE17: 3120478 | DF17: 3229968 | DG17: 3224547 | DH17: 3153658 | DI17: 3118855 | DJ17: 3010317 | DK17: 2986795 | DL17: 2911401 | DM17: 2917264 | DN17: 2896265 | DO17: 2846795 | DP17: 2816161 | DQ17: 2882699 | DR17: 2872688 | DS17: 2826729 | DT17: 2956553 | DU17: 2977694 | DV17: 2960241 | DW17: 2958885 | DX17: 3040516 | DY17: 3105305 | DZ17: 3066248 | EA17: 3046477 | EB17: 3092155 | EC17: 3019357 | ED17: 3041046 | EE17: 3114872 | EF17: 3121273 | EG17: 3155764 | EH17: 3157186 | EI17: 3121405 | EJ17: =EK17-EI17 -> 172415 | EK17: 3293820 | EL17: =EM17-EK17 -> -51225 | EM17: 3242595 | EN17: =EO17-EM17 -> 71201 | EO17: 3313796 | EP17: =EQ17-EO17 -> 35532 | EQ17: 3349328 | ER17: =ES17-EQ17 -> 53679 | ES17: 3403007 | ET17: =EU17-ES17 -> -60420 | EU17: 3342587 | EV17: =EW17-EU17 -> 39552 | EW17: 3382139 | EX17: 3313853 | EY17: 3190196 | EZ17: 3208091 | FA17: 3213495 | FB17: 3186251 | FC17: 3206508 | FD17: 3218320 | FE17: 3230059 | FF17: 3259097 | FG17: 3210496 | FH17: 3150150 | FI17: 3232770 | FJ17: 3178819
A18: Short-term | B18: 0 | C18: 0 | D18: 0 | E18: 0 | F18: 0 | G18: 0 | H18: 0 | I18: 0 | J18: 0 | K18: 0 | L18: 0 | M18: 0 | N18: 0 | O18: 0 | P18: 0 | Q18: 0 | R18: 0 | S18: 0 | T18: 0 | U18: 0 | V18: 0 | W18: 0 | X18: 0 | Y18: 0 | Z18: 0 | AA18: 0 | AB18: 0 | AC18: 0 | AD18: 0 | AE18: 0 | AF18: 0 | AG18: 0 | AH18: 0 | AI18: 0 | AJ18: 0 | AK18: 0 | AL18: 0 | AM18: 0 | AN18: 0 | AO18: 0 | AP18: 0 | AQ18: 0 | AR18: 10 | AS18: 10 | AT18: 334 | AU18: 316 | AV18: 5217 | AW18: 30739 | AX18: 956 | AY18: 38032 | AZ18: 43276 | BA18: 58233 | BB18: 6956 | BC18: 47156 | BD18: 81500 | BE18: 51423 | BF18: 63755 | BG18: 12860 | BH18: 55306 | BI18: 48503 | BJ18: 37360 | BK18: 112587 | BL18: 112587 | BM18: 34587 | BN18: 31587 | BO18: 69979 | BP18: 32687 | BQ18: 47355 | BR18: 55143 | BS18: 28946 | BT18: 55489 | BU18: 35156 | BV18: 10288 | BW18: 33513 | BX18: 36149 | BY18: 13271 | BZ18: 55253 | CA18: 69176 | CB18: 69855 | CC18: 114630 | CD18: 105195 | CE18: 151177 | CF18: 166574 | CG18: 156573 | CH18: 167664 | CI18: 194844 | CJ18: 175523 | CK18: 167411 | CL18: 159169 | CM18: 137372 | CN18: 160701 | CO18: 156711 | CP18: 145660 | CQ18: 133026 | CR18: 121510 | CS18: 108914 | CT18: 124089 | CU18: 116824 | CV18: 107806 | CW18: 96165 | CX18: 83113 | CY18: 72259 | CZ18: 67659 | DA18: 61844 | DB18: 58998 | DC18: 66474 | DD18: 73325 | DE18: 82949 | DF18: 90960 | DG18: 89487 | DH18: 74693 | DI18: 72307 | DJ18: 68243 | DK18: 74619 | DL18: 66508 | DM18: 83706 | DN18: 70009 | DO18: 67388 | DP18: 83963 | DQ18: 34207 | DR18: 28684 | DS18: 37262 | DT18: 38628 | DU18: 67926 | DV18: 49548 | DW18: 81018 | DX18: 74486 | DY18: 134024 | DZ18: 127099 | EA18: 169336 | EB18: 215483 | EC18: 126102 | ED18: 125709 | EE18: 214273 | EF18: 192283 | EG18: 203699 | EH18: 167935 | EI18: 166143 | EJ18: =EK18-EI18 -> -9067 | EK18: 157076 | EL18: =EM18-EK18 -> -7201 | EM18: 149875 | EN18: =EO18-EM18 -> -33359 | EO18: 116516 | EP18: =EQ18-EO18 -> 30339 | EQ18: 146855 | ER18: =ES18-EQ18 -> -24449 | ES18: 122406 | ET18: =EU18-ES18 -> -21341 | EU18: 101065 | EV18: =EW18-EU18 -> 11790 | EW18: 112855 | EX18: 94407 | EY18: 104771 | EZ18: 101459 | FA18: 100390 | FB18: 90027 | FC18: 80668 | FD18: 82735 | FE18: 81949 | FF18: 96079 | FG18: 93596 | FH18: 106517 | FI18: 124101 | FJ18: 123648
A19: Long-term | B19: 1136389 | C19: 1116889 | D19: 1200371 | E19: 1219871 | F19: 1242371 | G19: 1240425 | H19: 1233855 | I19: 1253510 | J19: 1265993 | K19: 1306554 | L19: 1372134 | M19: 1355316 | N19: 1354406 | O19: 1360463 | P19: 1338840 | Q19: 1337946 | R19: 1322946 | S19: 1343505 | T19: 1379623 | U19: 1367852 | V19: 1378488 | W19: 1420707 | X19: 1458707 | Y19: 1439110 | Z19: 1518473 | AA19: 1547368 | AB19: 1534883 | AC19: 1517104 | AD19: 1517563 | AE19: 1515042 | AF19: 1570534 | AG19: 1614034 | AH19: 1555502 | AI19: 1545062 | AJ19: 1566062 | AK19: 1566652 | AL19: 1585148 | AM19: 1547348 | AN19: 1472812 | AO19: 1489579 | AP19: 1495079 | AQ19: 1521581 | AR19: 1526008 | AS19: 1510508 | AT19: 1504009 | AU19: 1468023 | AV19: 1446023 | AW19: 1433251 | AX19: 1463386 | AY19: 1473411 | AZ19: 1456025 | BA19: 1474889 | BB19: 1499978 | BC19: 1593006 | BD19: 1582264 | BE19: 1575446 | BF19: 1564852 | BG19: 1563912 | BH19: 1632820 | BI19: 1645756 | BJ19: 1632338 | BK19: 1635999 | BL19: 1640187 | BM19: 1698862 | BN19: 1681074 | BO19: 1698727 | BP19: 1651065 | BQ19: 1730050 | BR19: 1775800 | BS19: 1773356 | BT19: 1758059 | BU19: 1776824 | BV19: 1851011 | BW19: 1868106 | BX19: 1881225 | BY19: 1930528 | BZ19: 1989881 | CA19: 2029000 | CB19: 2022672 | CC19: 2075492 | CD19: 2074468 | CE19: 2113692 | CF19: 2151215 | CG19: 2164908 | CH19: 2239850 | CI19: 2235473 | CJ19: 2289758 | CK19: 2315032 | CL19: 2303883 | CM19: 2306531 | CN19: 2265505 | CO19: 2368030 | CP19: 2405951 | CQ19: 2391347 | CR19: 2452363 | CS19: 2564167 | CT19: 2619837 | CU19: 2613839 | CV19: 2706578 | CW19: 2735329 | CX19: 2795115 | CY19: 2782535 | CZ19: 2916244 | DA19: 2920866 | DB19: 2950920 | DC19: 2994675 | DD19: 2980730 | DE19: 3037529 | DF19: 3139008 | DG19: 3135060 | DH19: 3078965 | DI19: 3046548 | DJ19: 2942074 | DK19: 2912177 | DL19: 2844893 | DM19: 2833558 | DN19: 2826256 | DO19: 2779406 | DP19: 2732199 | DQ19: 2848492 | DR19: 2844003 | DS19: 2789466 | DT19: 2917925 | DU19: 2909768 | DV19: 2910693 | DW19: 2877867 | DX19: 2966030 | DY19: 2971281 | DZ19: 2939148 | EA19: 2877141 | EB19: 2876672 | EC19: 2893255 | ED19: 2915338 | EE19: 2900599 | EF19: 2928990 | EG19: 2952064 | EH19: 2989250 | EI19: 2955262 | EJ19: =EK19-EI19 -> 181482 | EK19: 3136744 | EL19: =EM19-EK19 -> -44024 | EM19: 3092720 | EN19: =EO19-EM19 -> 104560 | EO19: 3197280 | EP19: =EQ19-EO19 -> 5193 | EQ19: 3202473 | ER19: =ES19-EQ19 -> 78129 | ES19: 3280602 | ET19: =EU19-ES19 -> -39081 | EU19: 3241521 | EV19: =EW19-EU19 -> 27762 | EW19: 3269283 | EX19: 3219446 | EY19: 3085425 | EZ19: 3106632 | FA19: 3113104 | FB19: 3096225 | FC19: 3125840 | FD19: 3135585 | FE19: 3148110 | FF19: 3163018 | FG19: 3116900 | FH19: 3043634 | FI19: 3108669 | FJ19: 3055171
A20: Long term, with a remaining maturity up to and including 1 year | BV20: 151691 | BW20: 168691 | BX20: 186191 | BY20: 190111 | BZ20: 194888 | CA20: 194104 | CB20: 255214 | CC20: 233654 | CD20: 220852 | CE20: 242852 | CF20: 234852 | CG20: 209052 | CH20: 281021 | CI20: 279021 | CJ20: 268821 | CK20: 329973 | CL20: 350978 | CM20: 345171 | CN20: 338530 | CO20: 380488 | CP20: 442576 | CQ20: 456594 | CR20: 469228 | CS20: 514268 | CT20: 454808 | CU20: 467798 | CV20: 539362 | CW20: 499447 | CX20: 510906 | CY20: 513419 | CZ20: 505469 | DA20: 506144 | DB20: 460501 | DC20: 432210 | DD20: 464584 | DE20: 438453 | DF20: 451371 | DG20: 487603 | DH20: 429934 | DI20: 419510 | DJ20: 389455 | DK20: 447384 | DL20: 445176 | DM20: 443007 | DN20: 461255 | DO20: 497395 | DP20: 588731 | DQ20: 639264 | DR20: 609957 | DS20: 587713 | DT20: 593414 | DU20: 590743 | DV20: 593026 | DW20: 566536 | DX20: 596109 | DY20: 577265 | DZ20: 554715 | EA20: 580480 | EB20: 457111 | EC20: 512920 | ED20: 569123 | EE20: 565462 | EF20: 611080 | EG20: 671192 | EH20: 653783 | EI20: 628990 | EJ20: =EK20-EI20 -> -50654 | EK20: 578336 | EL20: =EM20-EK20 -> 34410 | EM20: 612746 | EN20: =EO20-EM20 -> 22133 | EO20: 634879 | EP20: =EQ20-EO20 -> -39633 | EQ20: 595246 | ER20: =ES20-EQ20 -> 42938 | ES20: 638184 | ET20: =EU20-ES20 -> -70757 | EU20: 567427 | EV20: =EW20-EU20 -> -36647 | EW20: 530780 | EX20: 538890 | EY20: 476268 | EZ20: 395702 | FA20: 431632 | FB20: 534671 | FC20: 585002 | FD20: 568395 | FE20: 563608 | FF20: 565283 | FG20: 515920 | FH20: 472050 | FI20: 591706 | FJ20: 597122
A21: Long term, with a remaining maturity more than 1 year | BV21: 1699320 | BW21: 1699416 | BX21: 1695035 | BY21: 1740417 | BZ21: 1794993 | CA21: 1834896 | CB21: 1767459 | CC21: 1841839 | CD21: 1853616 | CE21: 1870840 | CF21: 1916363 | CG21: 1955856 | CH21: 1958828 | CI21: 1956451 | CJ21: 2020937 | CK21: 1985059 | CL21: 1952906 | CM21: 1961361 | CN21: 1926975 | CO21: 1987542 | CP21: 1963375 | CQ21: 1934752 | CR21: 1983134 | CS21: 2049898 | CT21: 2165028 | CU21: 2146041 | CV21: 2167217 | CW21: 2235882 | CX21: 2284209 | CY21: 2269116 | CZ21: 2410775 | DA21: 2414722 | DB21: 2490419 | DC21: 2562465 | DD21: 2516146 | DE21: 2599076 | DF21: 2687637 | DG21: 2647457 | DH21: 2649031 | DI21: 2627038 | DJ21: 2552619 | DK21: 2464793 | DL21: 2399718 | DM21: 2390551 | DN21: 2365001 | DO21: 2282011 | DP21: 2143468 | DQ21: 2209228 | DR21: 2234047 | DS21: 2201753 | DT21: 2324511 | DU21: 2319025 | DV21: 2317667 | DW21: 2311330 | DX21: 2369921 | DY21: 2394017 | DZ21: 2384433 | EA21: 2296661 | EB21: 2419561 | EC21: 2380335 | ED21: 2346215 | EE21: 2335137 | EF21: 2317910 | EG21: 2280873 | EH21: 2335467 | EI21: 2326273 | EJ21: =EK21-EI21 -> 232135 | EK21: 2558408 | EL21: =EM21-EK21 -> -78434 | EM21: 2479974 | EN21: =EO21-EM21 -> 82427 | EO21: 2562401 | EP21: =EQ21-EO21 -> 44825 | EQ21: 2607226 | ER21: =ES21-EQ21 -> 35192 | ES21: 2642418 | ET21: =EU21-ES21 -> 31677 | EU21: 2674095 | EV21: =EW21-EU21 -> 64409 | EW21: 2738504 | EX21: 2680556 | EY21: 2609157 | EZ21: 2710930 | FA21: 2681472 | FB21: 2561554 | FC21: 2540837 | FD21: 2567191 | FE21: 2584502 | FF21: 2597736 | FG21: 2600980 | FH21: 2571584 | FI21: 2516962 | FJ21: 2458049
A22: Insurance corporations | B22: 15000 | C22: 15000 | D22: 15000 | E22: 15000 | F22: 18000 | G22: 18000 | H22: 18000 | I22: 18000 | J22: 18000 | K22: 18000 | L22: 18000 | M22: 18000 | N22: 18000 | O22: 18000 | P22: 18000 | Q22: 18000 | R22: 18000 | S22: 18000 | T22: 18000 | U22: 18000 | V22: 18000 | W22: 18000 | X22: 18000 | Y22: 13000 | Z22: 13000 | AA22: 13000 | AB22: 13000 | AC22: 13000 | AD22: 13000 | AE22: 13000 | AF22: 13000 | AG22: 13000 | AH22: 13000 | AI22: 13000 | AJ22: 13000 | AK22: 13000 | AL22: 13000 | AM22: 13000 | AN22: 13000 | AO22: 13000 | AP22: 13000 | AQ22: 13000 | AR22: 13000 | AS22: 13000 | AT22: 13000 | AU22: 13000 | AV22: 13000 | AW22: 13000 | AX22: 13000 | AY22: 13000 | AZ22: 13000 | BA22: 13000 | BB22: 17000 | BC22: 17000 | BD22: 17000 | BE22: 17000 | BF22: 17000 | BG22: 12000 | BH22: 12000 | BI22: 7000 | BJ22: 7000 | BK22: 7000 | BL22: 7000 | BM22: 7000 | BN22: 7000 | BO22: 7000 | BP22: 7000 | BQ22: 7000 | BR22: 7000 | BS22: 7000 | BT22: 7000 | BU22: 7000 | BV22: 7000 | BW22: 7000 | BX22: 7000 | BY22: 7000 | BZ22: 7000 | CA22: 7000 | CB22: 7000 | CC22: 7000 | CD22: 7000 | CE22: 4000 | CF22: 7000 | CG22: 7000 | CH22: 7000 | CI22: 7000 | CJ22: 7282 | CK22: 7343 | CL22: 7043 | CM22: 7101 | CN22: 7157 | CO22: 7215 | CP22: 7273 | CQ22: 7329 | CR22: 7047 | CS22: 7103 | CT22: 7161 | CU22: 7219 | CV22: 7271 | CW22: 7329 | CX22: 7035 | CY22: 7082 | CZ22: 7127 | DA22: 7174 | DB22: 7221 | DC22: 7266 | DD22: 4021 | DE22: 4044 | DF22: 4068 | DG22: 4091 | DH22: 4113 | DI22: 4137 | DJ22: 0 | DK22: 0 | DL22: 0 | DM22: 0 | DN22: 0 | DO22: 0 | DP22: 0 | DQ22: 0 | DR22: 0 | DS22: 0 | DT22: 0 | DU22: 0 | DV22: 0 | DW22: 0 | DX22: 0 | DY22: 0 | DZ22: 0 | EA22: 0 | EB22: 0 | EC22: 0 | ED22: 0 | EE22: 0 | EF22: 0 | EG22: 0 | EH22: 0 | EI22: 0 | EJ22: =EK22-EI22 -> 0 | EK22: 0 | EL22: =EM22-EK22 -> 0 | EM22: 0 | EN22: =EO22-EM22 -> 0 | EO22: 0 | EP22: =EQ22-EO22 -> 0 | EQ22: 0 | ER22: =ES22-EQ22 -> 0 | ES22: 0 | ET22: =EU22-ES22 -> 0 | EU22: 0 | EV22: =EW22-EU22 -> 0 | EW22: 0 | EX22: 0 | EY22: 0 | EZ22: 0 | FA22: 0 | FB22: 0 | FC22: 0 | FD22: 0 | FE22: 0 | FF22: 0 | FG22: 0 | FH22: 0 | FI22: 0 | FJ22: 0
